<?xml version="1.0"?>

<robot name="ri4">
  <material name="red">
    <color rgba="1.0 0.0 0.0 2.0"/>
  </material>
  <material name="green">
    <color rgba="0.0 1.0 0.0 2.0"/>
  </material>
  <material name="blue">
    <color rgba="0.0 0.0 1.0 2.0"/>
  </material>
  <gazebo>
    <plugin name="gazebo_ros_control" filename="libgazebo_ros_control.so">
	    <robotNamespace>ri4</robotNamespace>
    </plugin>
  </gazebo>

<!-- ################################################################### -->
    <link name="base_link"> </link>
    
<!-- ################################################################### -->
  <joint name="joint0" type="fixed">
    <parent link="base_link"/>
    <child link="body1"/>
    <origin xyz= "1 1 1.05" rpy="0 0 0" />
  </joint>

<!-- doutai -->
  <link name="body1">
    <visual>
      <geometry> <box size="0.2 0.1 0.5"/> </geometry>
      <origin xyz="0 0 0.25" rpy="0 0 0"/>
      <material name="red"/>
    </visual>
    <collision>
      <geometry> <box size="0.2 0.1 0.5"/> </geometry>
      <origin xyz="0 0 0.25" rpy="0 0 0"/>
    </collision>
    <inertial>
      <origin xyz="0 0 0.25" rpy="0 0 0"/> 
      <mass value="20"/>
      <inertia ixx="5e-2" ixy="0" ixz="0" iyy="5e-2" iyz="0" izz="5e-2"/>
    </inertial>
  </link>
  <gazebo reference="body1"> <material>Gazebo/Red</material> </gazebo> 

<!-- ################################################################### -->
<!-- kokokara migi asi -->
<!-- migi kokansetu -->
  <joint name="joint1" type="revolute">
    <parent link="body1"/>
    <child link="body2"/>
    <origin xyz="0.1 0 0.0" rpy="0 0 0"/>
    <axis xyz="0 1 0"/>
    <limit effort="30" lower="-2.617" upper="2.617" velocity="1.571"/>
  </joint>
  <transmission name="trans1">
    <type>transmission_interface/SimpleTransmission</type>
    <joint name="joint1"> 
      <hardwareInterface>hardware_interface/EffortJointInterface</hardwareInterface> 
    </joint>
    <actuator name="motor1">
      <hardwareInterface>EffortJointInterface</hardwareInterface>
      <mechanicalReduction>1</mechanicalReduction>
    </actuator>
  </transmission>

<!-- migi ue sokeibu -->
  <link name="body2">
    <visual>
      <geometry> <box size="0.2 0.05 0.1"/> </geometry>
      <origin xyz="0.1 0 -0.05" rpy="0 0 0"/>
      <material name="blue"/>
    </visual>
    <collision>
      <geometry> <box size="0.2 0.05 0.1"/> </geometry>
      <origin xyz="0.1 0 -0.05" rpy="0 0 0"/>
    </collision>
    <inertial>
      <origin xyz="0.1 0 -0.05" rpy="0 0 0"/>  
      <mass value="0.1"/>
      <inertia ixx="5e-2" ixy="0" ixz="0" iyy="5e-2" iyz="0" izz="5e-2"/>
    </inertial>
  </link>
  <gazebo reference="body2"> <material>Gazebo/Blue</material> </gazebo> 

<!-- ################################################################### -->
<!-- migi kokansetu -->
  <joint name="joint2" type="revolute">
     <parent link="body2"/>
     <child link="body3"/>
     <origin xyz="0.1 0 -0.1" rpy="0 0 0"/>
     <axis xyz="1 0 0"/>
     <limit effort="30" lower="-2.617" upper="2.617" velocity="1.571"/>
  </joint>
  <transmission name="trans2">
    <type>transmission_interface/SimpleTransmission</type>
    <joint name="joint2">
      <hardwareInterface>hardware_interface/EffortJointInterface</hardwareInterface>
    </joint>
    <actuator name="motor2">
      <hardwareInterface>EffortJointInterface</hardwareInterface>
      <mechanicalReduction>1</mechanicalReduction>
    </actuator>
  </transmission>

<!-- migi futomomo -->
  <link name="body3">
    <visual>
      <geometry> <box size="0.1 0.02 0.4"/> </geometry>
      <origin xyz="0 0 -0.2" rpy="0 0 0"/>
      <material name="green"/>
    </visual>
    <collision>
      <origin xyz="0 0 -0.2" rpy="0 0 0"/>
      <geometry> <box size="0.1 0.02 0.4"/> </geometry>
    </collision>
    <inertial>
      <origin xyz="0 0 -0.2" rpy="0 0 0"/>  
      <mass value="0.1"/>
      <inertia ixx="5e-2" ixy="0" ixz="0" iyy="5e-2" iyz="0" izz="5e-2"/> 
    </inertial>
  </link>
  <gazebo reference="body3"> <material>Gazebo/Green</material> </gazebo> 

<!-- ################################################################### -->
<!-- migi hiza -->
  <joint name="joint3" type="revolute">
    <parent link="body3"/>
    <child link="body4"/>
    <origin xyz="0 0 -0.4" rpy="0 0 3.1415"/>
    <axis xyz="1 0 0"/>
    <limit effort="30" lower="-2.617" upper="2.617" velocity="1.571"/>
  </joint>
  <transmission name="trans3">
    <type>transmission_interface/SimpleTransmission</type>
    <joint name="joint3">
      <hardwareInterface>hardware_interface/EffortJointInterface</hardwareInterface>
    </joint>
    <actuator name="motor3">
      <hardwareInterface>EffortJointInterface</hardwareInterface>
      <mechanicalReduction>1</mechanicalReduction>
    </actuator>
  </transmission>

<!-- migi sune -->
  <link name="body4">
    <visual>
      <geometry> <box size="0.1 0.01 0.4"/> </geometry>
      <origin xyz="0 0 -0.2" rpy="0 0 0"/>
      <material name="red"/>
    </visual>
    <collision>
      <geometry> <box size="0.1 0.01 0.4"/> </geometry>
      <origin xyz="0 0 -0.2" rpy="0 0 0"/>
    </collision>
    <inertial>
      <origin xyz="0 0 -0.2" rpy="0 0 0"/> <!-- origin xyz="0 0 0.2" rpy="0 0 0"/ --> 
      <mass value="0.1"/>
      <inertia ixx="5e-2" ixy="0" ixz="0" iyy="5e-2" iyz="0" izz="5e-2"/>
    </inertial>
  </link>
  <gazebo reference="body4"> <material>Gazebo/Red</material> </gazebo> 

<!-- ################################################################### -->
<!-- migi kurubusi kansetu -->
  <joint name="joint4" type="revolute">
    <parent link="body4"/>
    <child link="body5"/>
    <origin xyz="0 0 -0.4" rpy="0 0 3.1415926"/>
    <axis xyz="1 0 0"/>
    <limit effort="30" lower="-2.617" upper="2.617" velocity="1.571"/>
  </joint>
  <transmission name="trans4">
    <type>transmission_interface/SimpleTransmission</type>
    <joint name="joint4">
      <hardwareInterface>hardware_interface/EffortJointInterface</hardwareInterface>
    </joint>
    <actuator name="motor4">
      <hardwareInterface>EffortJointInterface</hardwareInterface>
      <mechanicalReduction>1</mechanicalReduction>
    </actuator>
  </transmission>

<!-- migi kurubusi -->
  <link name="body5">
    <visual>
      <geometry> <box size="0.2 0.05 0.1"/> </geometry>
      <origin xyz="0 0 -0.05" rpy="0 0 0"/>
      <material name="green"/>
    </visual>
    <inertial>
      <origin xyz="0 0 -0.05" rpy="0 0 0"/>
      <mass value="0.1"/>
      <inertia ixx="5e-2" ixy="0" ixz="0" iyy="5e-2" iyz="0" izz="5e-2"/>
    </inertial>
  </link>
  <gazebo reference="body5"> <material>Gazebo/Green</material> </gazebo> 

<!-- ################################################################### -->
<!-- migi kurubisi sita -->
  <joint name="joint5" type="revolute">
    <parent link="body5"/>
    <child link="body6"/>
    <origin xyz="0 0 -0.1" rpy="0 0 0"/>
    <axis xyz="0 1 0"/>
    <limit effort="30" lower="-2.617" upper="2.617" velocity="1.571"/>
  </joint>
  <transmission name="trans5">
    <type>transmission_interface/SimpleTransmission</type>
    <joint name="joint5">
      <hardwareInterface>hardware_interface/EffortJointInterface</hardwareInterface>
    </joint>
    <actuator name="motor5">
      <hardwareInterface>EffortJointInterface</hardwareInterface>
      <mechanicalReduction>1</mechanicalReduction>
    </actuator>
  </transmission>

<!-- migi asi ura -->
  <link name="body6">
    <visual>
      <geometry> <box size="0.2 0.3 0.01"/> </geometry>
      <origin xyz="0 0 -0.005" rpy="0 0 0"/>
      <material name="blue"/>
    </visual>
    <collision>
      <geometry> <box size="0.2 0.3 0.01"/> </geometry>
      <origin xyz="0 0 -0.005" rpy="0 0 0"/>
    </collision>
    <inertial>
      <origin xyz="0 0 -0.005" rpy="0 0 0"/>
      <mass value="0.1"/>
      <inertia ixx="5e-2" ixy="0" ixz="0" iyy="5e-2" iyz="0" izz="5e-2"/>
    </inertial>
  </link>
  <gazebo reference="body6"> <material>Gazebo/Blue</material> </gazebo> 

<!-- ################################################################### -->
<!-- kokokara hidari asi -->
<!-- hidariasi kokansetu -->
  <joint name="joint6" type="revolute">
    <parent link="body1"/>
    <child  link="body7"/>
    <origin xyz="-0.1 0 0.0" rpy="0 0 0"/>
    <axis xyz="0 -1 0"/>
    <limit effort="30" lower="-2.617" upper="2.617" velocity="1.571"/>
  </joint>
  <transmission name="trans6">
    <type>transmission_interface/SimpleTransmission</type>
    <joint name="joint6">
      <hardwareInterface>hardware_interface/EffortJointInterface</hardwareInterface>
    </joint>
    <actuator name="motor6">
      <hardwareInterface>EffortJointInterface</hardwareInterface>
      <mechanicalReduction>1</mechanicalReduction>
    </actuator>
  </transmission>

<!-- hidari ue sokeibu -->
  <link name="body7">
    <visual>
      <geometry> <box size="0.2 0.05 0.1"/> </geometry>
      <origin xyz="-0.1 0 -0.05" rpy="0 0 0"/>
      <material name="blue"/>
    </visual>
    <collision>
      <geometry> <box size="0.2 0.05 0.1"/> </geometry>
      <origin xyz="-0.1 0 -0.05" rpy="0 0 0"/>
    </collision>
    <inertial>
      <origin xyz="-0.1 0 -0.05" rpy="0 0 0"/>
      <mass value="0.1"/>
      <inertia ixx="5e-2" ixy="0" ixz="0" iyy="5e-2" iyz="0" izz="5e-2"/>
    </inertial>
  </link>
  <gazebo reference="body7"> <material>Gazebo/Blue</material> </gazebo> 

<!-- ################################################################### -->
<!-- hidari kokansetu -->
  <joint name="joint7" type="revolute">
     <parent link="body7"/>
     <child  link="body8"/>
     <origin xyz="-0.1 0 -0.1" rpy="0 0 0"/>
     <axis xyz="1 0 0"/>
     <limit effort="30" lower="-2.617" upper="2.617" velocity="1.571"/>
  </joint>
  <transmission name="trans7">
    <type>transmission_interface/SimpleTransmission</type>
    <joint name="joint7">
      <hardwareInterface>hardware_interface/EffortJointInterface</hardwareInterface>
    </joint>
    <actuator name="motor7">
      <hardwareInterface>EffortJointInterface</hardwareInterface>
      <mechanicalReduction>1</mechanicalReduction>
    </actuator>
  </transmission>

<!-- hidari futomomo -->
  <link name="body8">
    <visual>
      <geometry> <box size="0.1 0.02 0.4"/> </geometry>
      <origin xyz="0 0 -0.2" rpy="0 0 0"/>
      <material name="green"/>
    </visual>
    <collision>
      <origin xyz="0 0 -0.2" rpy="0 0 0"/>
      <geometry> <box size="0.1 0.02 0.4"/> </geometry>
    </collision>
    <inertial>
      <origin xyz="0 0 -0.2" rpy="0 0 0"/>  
      <mass value="0.1"/>
      <inertia ixx="5e-2" ixy="0" ixz="0" iyy="5e-2" iyz="0" izz="5e-2"/> 
    </inertial>
  </link>
  <gazebo reference="body8"> <material>Gazebo/Green</material> </gazebo> 

<!-- ################################################################### -->
<!-- hidari hiza -->
  <joint name="joint8" type="revolute">
    <parent link="body8"/>
    <child link="body9"/>
    <origin xyz="0 0 -0.4" rpy="0 0 3.1415"/>
    <axis xyz="1 0 0"/>
    <limit effort="30" lower="-2.617" upper="2.617" velocity="1.571"/>
  </joint>
  <transmission name="trans8">
    <type>transmission_interface/SimpleTransmission</type>
    <joint name="joint8">
      <hardwareInterface>hardware_interface/EffortJointInterface</hardwareInterface>
    </joint>
    <actuator name="motor8">
      <hardwareInterface>EffortJointInterface</hardwareInterface>
      <mechanicalReduction>1</mechanicalReduction>
    </actuator>
  </transmission>

<!-- hidari sune -->
  <link name="body9">
    <visual>
      <geometry> <box size="0.1 0.01 0.4"/> </geometry>
      <origin xyz="0 0 -0.2" rpy="0 0 0"/>
      <material name="red"/>
    </visual>
    <collision>
      <geometry> <box size="0.1 0.01 0.4"/> </geometry>
      <origin xyz="0 0 -0.2" rpy="0 0 0"/>
    </collision>
    <inertial>
      <origin xyz="0 0 -0.2" rpy="0 0 0"/>  
      <mass value="0.1"/>
      <inertia ixx="5e-2" ixy="0" ixz="0" iyy="5e-2" iyz="0" izz="5e-2"/>
    </inertial>
  </link>
  <gazebo reference="body9"> <material>Gazebo/Red</material> </gazebo> 

<!-- ################################################################### -->
<!-- hidari kurubusi kansetu -->
  <joint name="joint9" type="revolute">
    <parent link="body9"/>
    <child  link="body10"/>
    <origin xyz="0 0 -0.4" rpy="0 0 3.1415926"/>
    <axis xyz="1 0 0"/>
    <limit effort="30" lower="-2.617" upper="2.617" velocity="1.571"/>
  </joint>
  <transmission name="trans9">
    <type>transmission_interface/SimpleTransmission</type>
    <joint name="joint9">
      <hardwareInterface>hardware_interface/EffortJointInterface</hardwareInterface>
    </joint>
    <actuator name="motor9">
      <hardwareInterface>EffortJointInterface</hardwareInterface>
      <mechanicalReduction>1</mechanicalReduction>
    </actuator>
  </transmission>

<!-- hidari kurubusi -->
  <link name="body10">
    <visual>
      <geometry> <box size="0.2 0.05 0.1"/> </geometry>
      <origin xyz="0 0 -0.05" rpy="0 0 0"/>
      <material name="green"/>
    </visual>
    <inertial>
      <origin xyz="0 0 -0.05" rpy="0 0 0"/>
      <mass value="0.1"/>
      <inertia ixx="5e-2" ixy="0" ixz="0" iyy="5e-2" iyz="0" izz="5e-2"/>
    </inertial>
  </link>
  <gazebo reference="body10"> <material>Gazebo/Green</material> </gazebo> 

<!-- ################################################################### -->
<!-- hidari kurubisi sita -->
  <joint name="joint10" type="revolute">
    <parent link="body10"/>
    <child  link="body11"/>
    <origin xyz="0 0 -0.1" rpy="0 0 0"/>
    <axis xyz="0 -1 0"/>
    <limit effort="30" lower="-2.617" upper="2.617" velocity="1.571"/>
  </joint>
  <transmission name="trans10">
    <type>transmission_interface/SimpleTransmission</type>
    <joint name="joint10">
      <hardwareInterface>hardware_interface/EffortJointInterface</hardwareInterface>
    </joint>
    <actuator name="motor10">
      <hardwareInterface>EffortJointInterface</hardwareInterface>
      <mechanicalReduction>1</mechanicalReduction>
    </actuator>
  </transmission>

<!-- hidari asi ura -->
  <link name="body11">
    <visual>
      <geometry> <box size="0.2 0.3 0.01"/> </geometry>
      <origin xyz="0 0 -0.005" rpy="0 0 0"/>
      <material name="blue"/>
    </visual>
    <collision>
      <geometry> <box size="0.2 0.3 0.01"/> </geometry>
      <origin xyz="0 0 -0.005" rpy="0 0 0"/>
    </collision>
    <inertial>
      <origin xyz="0 0 -0.005" rpy="0 0 0"/>
      <mass value="0.1"/>
      <inertia ixx="5e-2" ixy="0" ixz="0" iyy="5e-2" iyz="0" izz="5e-2"/>
    </inertial>
  </link>
  <gazebo reference="body11"> <material>Gazebo/Blue</material> </gazebo> 

<!-- ################################################################### -->
<!-- migi kata kansetu y -->
  <joint name="joint11" type="fixed">
    <parent link="body1"/>
    <child  link="body12"/>
    <origin xyz="0.1 0 0.5" rpy="0 0 0"/>
    <axis xyz="0 1 0"/>
  </joint>

<!-- migi kata -->
  <link name="body12">
    <visual>
      <geometry> <box size="0.3 0.05 0.1"/> </geometry>
      <origin xyz="0.15 0 -0.05" rpy="0 0 0"/>
      <material name="blue"/>
    </visual>
  </link>
  <gazebo reference="body12"> <material>Gazebo/Blue</material> </gazebo> 

<!-- ################################################################### -->
<!-- migi kata kansetu x -->
  <joint name="joint12" type="fixed">
    <parent link="body12"/>
    <child  link="body13"/>
    <origin xyz="0.3 0 -0.1" rpy="0 0 0"/>
  </joint>

<!-- migi jyouwan -->
  <link name="body13">
    <visual>
      <geometry> <box size="0.1 0.02 0.3"/> </geometry>
      <origin xyz="0 0 -0.15" rpy="0 0 0"/>
      <material name="green"/>
    </visual>
  </link>
  <gazebo reference="body13"> <material>Gazebo/Green</material> </gazebo> 

<!-- ################################################################### -->
<!-- migi hiji -->
  <joint name="joint13" type="fixed">
    <parent link="body13"/>
    <child  link="body14"/>
    <origin xyz="0 0 -.3" rpy="0 0 0"/>
  </joint>

<!-- migi zenwan -->
  <link name="body14">
    <visual>
      <geometry> <box size="0.1 0.1 0.3"/> </geometry>
      <origin xyz="0 0 -0.15" rpy="0 0 0"/>
      <material name="red"/>
    </visual>
  </link>
  <gazebo reference="body14"> <material>Gazebo/Red</material> </gazebo> 

<!-- ################################################################### -->
<!-- hidari kata y -->
  <joint name="joint14" type="fixed">
    <parent link="body1"/>
    <child  link="body15"/>
    <origin xyz="-0.1 0 0.5" rpy="0 0 0"/>
    <axis xyz="0 1 0"/>
  </joint>

<!-- hidari kata -->
 <link name="body15">
    <visual>
      <geometry> <box size="0.3 0.05 0.1"/> </geometry>
      <origin xyz="-0.15 0 -0.05" rpy="0 0 0"/>
      <material name="blue"/>
    </visual>
  </link>
  <gazebo reference="body15"> <material>Gazebo/Blue</material> </gazebo> 

<!-- ################################################################### -->
<!-- hidari kata x -->
  <joint name="joint15" type="fixed">
    <parent link="body15"/>
    <child  link="body16"/>
    <origin xyz="-0.3 0 -0.1" rpy="0 0 3.1415"/>
  </joint>

<!-- hidari jyouwan -->
  <link name="body16">
    <visual>
      <geometry> <box size="0.1 0.02 0.3"/> </geometry>
      <origin xyz="0 0 -0.15" rpy="0 0 0"/>
      <material name="green"/>
    </visual>
  </link>
  <gazebo reference="body16"> <material>Gazebo/Green</material> </gazebo> 

<!-- ################################################################### -->
<!-- hidari hiji -->
  <joint name="joint16" type="fixed">
    <parent link="body16"/>
    <child  link="body17"/>
    <origin xyz="0 0 -0.3" rpy="0 0 0"/>
  </joint>

<!-- hidari zenwan -->
  <link name="body17">
    <visual>
      <geometry> <box size="0.1 0.1 0.3"/> </geometry>
      <origin xyz="0 0 -0.15" rpy="0 0 0"/>
      <material name="red"/>
    </visual>
  </link>
  <gazebo reference="body17"> <material>Gazebo/Red</material> </gazebo> 

</robot>
