<?xml version="1.0"?>

<robot name="ri4">
    <gazebo>
      <plugin name="gazebo_ros_control" filename="libgazebo_ros_control.so">
	<robotNamespace>ri4</robotNamespace>
      </plugin>
    </gazebo>

<!-- ################################################################### -->

    <link name="base_link"> </link>
    
<!-- ################################################################### -->

    <joint name="joint0" type="fixed">
        <parent link="base_link"/>
	<child link="body"/>
	<origin xyz= "1 1 1" rpy="0 0 0" />
    </joint>

    <link name="body">
        <visual>
	    <origin xyz="0 0 0" rpy="0 0 0"/>
	    <geometry> <box size="0.8 0.4 0.6"/> </geometry>
	</visual>
	<collision>
	    <origin xyz="0 0 0" rpy="0 0 0"/>
	    <geometry> <box size="0.8 0.4 0.6"/> </geometry>
	</collision>
	<inertial>
	    <origin xyz="0 0 0" rpy="0 0 0"/> <mass value="20"/>
	    <inertia ixx="5e-2" ixy="0" ixz="0" iyy="5e-2" iyz="0" izz="5e-2"/>
	</inertial>
    </link>

<!-- ################################################################### -->

    <joint name="joint1" type="revolute">
        <parent link="body"/>
	<child link="link1"/>
	<origin xyz= "0 0 0.3" rpy="0 0 0" />
	<axis xyz="0 1 0"/>
	<limit effort="30" lower="-2.617" upper="2.617" velocity="1.571"/>
    </joint>

    <link name="link1">
        <visual>
	    <origin xyz="0 0 0.25" rpy="0 0 0"/>
	    <geometry> <cylinder length="0.5" radius="0.1"/> </geometry>
	</visual>
	<collision>
	    <origin xyz="0 0 0.25" rpy="0 0 0"/>
	    <geometry> <cylinder length="0.5" radius="0.1"/> </geometry>
	</collision>
	<inertial>
	    <origin xyz="0 0 0.25" rpy="0 0 0"/> <mass value="0.1"/>
	    <inertia ixx="5e-2" ixy="0" ixz="0" iyy="5e-2" iyz="0" izz="5e-2"/>
	</inertial>
    </link>

    <transmission name="trans1">
      <type>transmission_interface/SimpleTransmission</type>
      <joint name="joint1">
	<hardwareInterface>EffortJointInterface</hardwareInterface>
      </joint>
      <actuator name="motor1">
	<hardwareInterface>EffortJointInterface</hardwareInterface>
	<mechanicalReduction>1</mechanicalReduction>
      </actuator>
    </transmission>

<!-- ################################################################### -->

    <joint name="joint2" type="revolute">
        <parent link="link1"/>
	<child link="link2"/>
	<origin xyz= "0 0 0.5" rpy="0 0 0" />
	<axis xyz="1 0 0"/>
	<limit effort="30" lower="-2.617" upper="2.617" velocity="1.571"/>
    </joint>

    <link name="link2">
        <visual>
	    <origin xyz="0 0 0.25" rpy="0 0 0"/>
	    <geometry> <cylinder length="0.5" radius="0.1"/> </geometry>
	</visual>
	<collision>
	    <origin xyz="0 0 0.25" rpy="0 0 0"/>
	    <geometry> <cylinder length="0.5" radius="0.1"/> </geometry>
	</collision>
	<inertial>
	    <origin xyz="0 0 0.25" rpy="0 0 0"/> <mass value="0.1"/>
	    <inertia ixx="5e-2" ixy="0" ixz="0" iyy="5e-2" iyz="0" izz="5e-2"/>
	</inertial>
    </link>

    <transmission name="trans2">
      <type>transmission_interface/SimpleTransmission</type>
      <joint name="joint2">
	<hardwareInterface>EffortJointInterface</hardwareInterface>
      </joint>
      <actuator name="motor2">
	<hardwareInterface>EffortJointInterface</hardwareInterface>
	<mechanicalReduction>1</mechanicalReduction>
      </actuator>
    </transmission>

<!-- ################################################################### -->

    <joint name="joint3" type="revolute">
        <parent link="link2"/>
	<child link="link3"/>
	<origin xyz= "0 0 0.5" rpy="0 0 0" />
	<axis xyz="0 0 1"/>
	<limit effort="30" lower="-2.617" upper="2.617" velocity="1.571"/>
    </joint>

    <link name="link3">
        <visual>
	    <origin xyz="0 0 0.2" rpy="0 0 0"/>
	    <geometry> <box size="0.6 0.1 0.4"/> </geometry>
	</visual>
	<collision>
	    <origin xyz="0 0 0.2" rpy="0 0 0"/>
	    <geometry> <box size="0.6 0.1 0.4"/> </geometry>
	</collision>
	<inertial>
	    <origin xyz="0 0 0.2" rpy="0 0 0"/> <mass value="0.1"/>
	    <inertia ixx="5e-2" ixy="0" ixz="0" iyy="5e-2" iyz="0" izz="5e-2"/>
	</inertial>
    </link>

    <transmission name="trans3">
      <type>transmission_interface/SimpleTransmission</type>
      <joint name="joint3">
	<hardwareInterface>EffortJointInterface</hardwareInterface>
      </joint>
      <actuator name="motor3">
	<hardwareInterface>EffortJointInterface</hardwareInterface>
	<mechanicalReduction>1</mechanicalReduction>
      </actuator>
    </transmission>

<!-- ################################################################### -->

    <joint name="jointx" type="revolute">
        <parent link="body"/>
	<child link="linkx"/>
	<origin xyz= "0.4 0 0.3" rpy="0 0 0" />
	<axis xyz="1 0 0"/>
	<limit effort="30" lower="-2.617" upper="2.617" velocity="1.571"/>
    </joint>

    <link name="linkx">
        <visual>
	    <origin xyz="0.2 0 0" rpy="0 0 0"/>
	    <geometry> <box size="0.4 0.1 0.1"/> </geometry>
	</visual>
	<collision>
	    <origin xyz="0.2 0 0" rpy="0 0 0"/>
	    <geometry> <box size="0.4 0.1 0.1"/> </geometry>
	</collision>
	<inertial>
	    <origin xyz="0.2 0 0" rpy="0 0 0"/> <mass value="0.1"/>
	    <inertia ixx="5e-2" ixy="0" ixz="0" iyy="5e-2" iyz="0" izz="5e-2"/>
	</inertial>
    </link>

    <transmission name="transx">
      <type>transmission_interface/SimpleTransmission</type>
      <joint name="jointx">
	<hardwareInterface>EffortJointInterface</hardwareInterface>
      </joint>
      <actuator name="motorx">
	<hardwareInterface>EffortJointInterface</hardwareInterface>
	<mechanicalReduction>1</mechanicalReduction>
      </actuator>
    </transmission>

<!-- ################################################################### -->

    <joint name="jointx2" type="fixed">
        <parent link="linkx"/>
	<child link="linkx2"/>
	<origin xyz= "0.4 0 0" rpy="0 0 0" />
    </joint>

    <link name="linkx2">
        <visual>
	    <origin xyz="0 0 -0.2" rpy="0 0 0"/>
	    <geometry> <box size="0.1 0.1 0.4"/> </geometry>
	</visual>
	<collision>
	    <origin xyz="0 0 -0.2" rpy="0 0 0"/>
	    <geometry> <box size="0.1 0.1 0.4"/> </geometry>
	</collision>
	<inertial>
	    <origin xyz="0 0 -0.2" rpy="0 0 0"/> <mass value="0.1"/>
	    <inertia ixx="5e-2" ixy="0" ixz="0" iyy="5e-2" iyz="0" izz="5e-2"/>
	</inertial>
    </link>

<!-- ################################################################### -->

    <joint name="jointy" type="revolute">
        <parent link="body"/>
	<child link="linky"/>
	<origin xyz= "0 0.2 0.3" rpy="0 0 0" />
	<axis xyz="0 1 0"/>
	<limit effort="30" lower="-2.617" upper="2.617" velocity="1.571"/>
    </joint>

    <link name="linky">
        <visual>
	    <origin xyz="0 0.4 0" rpy="0 0 0"/>
	    <geometry> <box size="0.1 0.8 0.1"/> </geometry>
	</visual>
	<collision>
	    <origin xyz="0 0.4 0" rpy="0 0 0"/>
	    <geometry> <box size="0.1 0.8 0.1"/> </geometry>
	</collision>
	<inertial>
	    <origin xyz="0 0.4 0" rpy="0 0 0"/> <mass value="0.1"/>
	    <inertia ixx="5e-2" ixy="0" ixz="0" iyy="5e-2" iyz="0" izz="5e-2"/>
	</inertial>
    </link>

    <transmission name="transy">
      <type>transmission_interface/SimpleTransmission</type>
      <joint name="jointy">
	<hardwareInterface>EffortJointInterface</hardwareInterface>
      </joint>
      <actuator name="motory">
	<hardwareInterface>EffortJointInterface</hardwareInterface>
	<mechanicalReduction>1</mechanicalReduction>
      </actuator>
    </transmission>

</robot>



















